Traceback (most recent call last):
  File "C:\Users\Luis\anaconda3\lib\site-packages\jupyter_cache\executors\utils.py", line 58, in single_nb_execution
    executenb(
  File "C:\Users\Luis\anaconda3\lib\site-packages\nbclient\client.py", line 1204, in execute
    return NotebookClient(nb=nb, resources=resources, km=km, **kwargs).execute()
  File "C:\Users\Luis\anaconda3\lib\site-packages\nbclient\util.py", line 84, in wrapped
    return just_run(coro(*args, **kwargs))
  File "C:\Users\Luis\anaconda3\lib\site-packages\nbclient\util.py", line 62, in just_run
    return loop.run_until_complete(coro)
  File "C:\Users\Luis\anaconda3\lib\asyncio\base_events.py", line 647, in run_until_complete
    return future.result()
  File "C:\Users\Luis\anaconda3\lib\site-packages\nbclient\client.py", line 663, in async_execute
    await self.async_execute_cell(
  File "C:\Users\Luis\anaconda3\lib\site-packages\nbclient\client.py", line 965, in async_execute_cell
    await self._check_raise_for_error(cell, cell_index, exec_reply)
  File "C:\Users\Luis\anaconda3\lib\site-packages\nbclient\client.py", line 862, in _check_raise_for_error
    raise CellExecutionError.from_cell_and_msg(cell, exec_reply_content)
nbclient.exceptions.CellExecutionError: An error occurred while executing the following cell:
------------------
import numpy as np
import nbconvert as nbc
from ipywidgets import interact
import nbinteract as nbi

nbi.multiple_choice(question="What is 10 + 2 * 5?",
                    choices=['12', '60', '20'],
                    answer=2)

nbi.multiple_choice(question="Select all prime numbers.",
                    choices=['12', '3', '31'],
                    answer=[1, 2])

nbi.short_answer('What is 1+1?', answers='2', explanation='1+1 is 2')

nbi.short_answer('Enter the first name of a member of the Beatles.',
                 ['John', 'Paul', 'George', 'Ringo'])
------------------

[1;31m---------------------------------------------------------------------------[0m
[1;31mTypeError[0m                                 Traceback (most recent call last)
[1;32m~\AppData\Local\Temp/ipykernel_9540/3084084145.py[0m in [0;36m<module>[1;34m[0m
[0;32m      4[0m [1;32mimport[0m [0mnbinteract[0m [1;32mas[0m [0mnbi[0m[1;33m[0m[1;33m[0m[0m
[0;32m      5[0m [1;33m[0m[0m
[1;32m----> 6[1;33m nbi.multiple_choice(question="What is 10 + 2 * 5?",
[0m[0;32m      7[0m                     [0mchoices[0m[1;33m=[0m[1;33m[[0m[1;34m'12'[0m[1;33m,[0m [1;34m'60'[0m[1;33m,[0m [1;34m'20'[0m[1;33m][0m[1;33m,[0m[1;33m[0m[1;33m[0m[0m
[0;32m      8[0m                     answer=2)

[1;31mTypeError[0m: multiple_choice() got an unexpected keyword argument 'answer'
TypeError: multiple_choice() got an unexpected keyword argument 'answer'

